2020-04-17 19:22:14,858 ERROR: Exception on /favicon.ico [GET] [in c:\users\manuel.robalinho\appdata\local\programs\python\python37-32\lib\site-packages\flask\app.py:1892]
Traceback (most recent call last):
  File "c:\users\manuel.robalinho\appdata\local\programs\python\python37-32\lib\site-packages\sqlalchemy\engine\base.py", line 755, in _commit_impl
    self.engine.dialect.do_commit(self.connection)
  File "c:\users\manuel.robalinho\appdata\local\programs\python\python37-32\lib\site-packages\sqlalchemy\engine\default.py", line 543, in do_commit
    dbapi_connection.commit()
sqlite3.OperationalError: database is locked

The above exception was the direct cause of the following exception:

Traceback (most recent call last):
  File "c:\users\manuel.robalinho\appdata\local\programs\python\python37-32\lib\site-packages\flask\app.py", line 2447, in wsgi_app
    response = self.full_dispatch_request()
  File "c:\users\manuel.robalinho\appdata\local\programs\python\python37-32\lib\site-packages\flask\app.py", line 1952, in full_dispatch_request
    rv = self.handle_user_exception(e)
  File "c:\users\manuel.robalinho\appdata\local\programs\python\python37-32\lib\site-packages\flask\app.py", line 1821, in handle_user_exception
    reraise(exc_type, exc_value, tb)
  File "c:\users\manuel.robalinho\appdata\local\programs\python\python37-32\lib\site-packages\flask\_compat.py", line 39, in reraise
    raise value
  File "c:\users\manuel.robalinho\appdata\local\programs\python\python37-32\lib\site-packages\flask\app.py", line 1948, in full_dispatch_request
    rv = self.preprocess_request()
  File "c:\users\manuel.robalinho\appdata\local\programs\python\python37-32\lib\site-packages\flask\app.py", line 2242, in preprocess_request
    rv = func()
  File "C:\Users\manuel.robalinho\Google Drive\Trab_Academicos\FLASK\microblog\app\main\routes.py", line 20, in before_request
    db.session.commit()
  File "c:\users\manuel.robalinho\appdata\local\programs\python\python37-32\lib\site-packages\sqlalchemy\orm\scoping.py", line 162, in do
    return getattr(self.registry(), name)(*args, **kwargs)
  File "c:\users\manuel.robalinho\appdata\local\programs\python\python37-32\lib\site-packages\sqlalchemy\orm\session.py", line 1036, in commit
    self.transaction.commit()
  File "c:\users\manuel.robalinho\appdata\local\programs\python\python37-32\lib\site-packages\sqlalchemy\orm\session.py", line 507, in commit
    t[1].commit()
  File "c:\users\manuel.robalinho\appdata\local\programs\python\python37-32\lib\site-packages\sqlalchemy\engine\base.py", line 1736, in commit
    self._do_commit()
  File "c:\users\manuel.robalinho\appdata\local\programs\python\python37-32\lib\site-packages\sqlalchemy\engine\base.py", line 1767, in _do_commit
    self.connection._commit_impl()
  File "c:\users\manuel.robalinho\appdata\local\programs\python\python37-32\lib\site-packages\sqlalchemy\engine\base.py", line 757, in _commit_impl
    self._handle_dbapi_exception(e, None, None, None, None)
  File "c:\users\manuel.robalinho\appdata\local\programs\python\python37-32\lib\site-packages\sqlalchemy\engine\base.py", line 1482, in _handle_dbapi_exception
    sqlalchemy_exception, with_traceback=exc_info[2], from_=e
  File "c:\users\manuel.robalinho\appdata\local\programs\python\python37-32\lib\site-packages\sqlalchemy\util\compat.py", line 178, in raise_
    raise exception
  File "c:\users\manuel.robalinho\appdata\local\programs\python\python37-32\lib\site-packages\sqlalchemy\engine\base.py", line 755, in _commit_impl
    self.engine.dialect.do_commit(self.connection)
  File "c:\users\manuel.robalinho\appdata\local\programs\python\python37-32\lib\site-packages\sqlalchemy\engine\default.py", line 543, in do_commit
    dbapi_connection.commit()
sqlalchemy.exc.OperationalError: (sqlite3.OperationalError) database is locked
(Background on this error at: http://sqlalche.me/e/e3q8)
2020-04-17 19:23:11,019 INFO: Microblog startup [in C:\Users\manuel.robalinho\Google Drive\Trab_Academicos\FLASK\microblog\app\__init__.py:77]
