2020-04-11 17:30:19,353 INFO: Microblog startup [in C:\Users\manuel.robalinho\Google Drive\Trab_Academicos\FLASK\microblog\app\__init__.py:48]
2020-04-11 19:09:20,962 INFO: Microblog startup [in C:\Users\manuel.robalinho\Google Drive\Trab_Academicos\FLASK\microblog\app\__init__.py:50]
2020-04-11 23:05:01,234 INFO: Microblog startup [in C:\Users\manuel.robalinho\Google Drive\Trab_Academicos\FLASK\microblog\app\__init__.py:53]
2020-04-12 16:58:12,157 INFO: Microblog startup [in C:\Users\manuel.robalinho\Google Drive\Trab_Academicos\FLASK\microblog\app\__init__.py:53]
2020-04-12 16:58:18,170 ERROR: Exception on /user/Manuel [GET] [in c:\users\manuel.robalinho\appdata\local\programs\python\python37-32\lib\site-packages\flask\app.py:1892]
Traceback (most recent call last):
  File "c:\users\manuel.robalinho\appdata\local\programs\python\python37-32\lib\site-packages\flask\app.py", line 2447, in wsgi_app
    response = self.full_dispatch_request()
  File "c:\users\manuel.robalinho\appdata\local\programs\python\python37-32\lib\site-packages\flask\app.py", line 1952, in full_dispatch_request
    rv = self.handle_user_exception(e)
  File "c:\users\manuel.robalinho\appdata\local\programs\python\python37-32\lib\site-packages\flask\app.py", line 1821, in handle_user_exception
    reraise(exc_type, exc_value, tb)
  File "c:\users\manuel.robalinho\appdata\local\programs\python\python37-32\lib\site-packages\flask\_compat.py", line 39, in reraise
    raise value
  File "c:\users\manuel.robalinho\appdata\local\programs\python\python37-32\lib\site-packages\flask\app.py", line 1948, in full_dispatch_request
    rv = self.preprocess_request()
  File "c:\users\manuel.robalinho\appdata\local\programs\python\python37-32\lib\site-packages\flask\app.py", line 2242, in preprocess_request
    rv = func()
  File "C:\Users\manuel.robalinho\Google Drive\Trab_Academicos\FLASK\microblog\app\routes.py", line 16, in before_request
    g.locale = str(get_locale())
NameError: name 'g' is not defined
2020-04-12 16:58:25,850 ERROR: Exception on / [GET] [in c:\users\manuel.robalinho\appdata\local\programs\python\python37-32\lib\site-packages\flask\app.py:1892]
Traceback (most recent call last):
  File "c:\users\manuel.robalinho\appdata\local\programs\python\python37-32\lib\site-packages\flask\app.py", line 2447, in wsgi_app
    response = self.full_dispatch_request()
  File "c:\users\manuel.robalinho\appdata\local\programs\python\python37-32\lib\site-packages\flask\app.py", line 1952, in full_dispatch_request
    rv = self.handle_user_exception(e)
  File "c:\users\manuel.robalinho\appdata\local\programs\python\python37-32\lib\site-packages\flask\app.py", line 1821, in handle_user_exception
    reraise(exc_type, exc_value, tb)
  File "c:\users\manuel.robalinho\appdata\local\programs\python\python37-32\lib\site-packages\flask\_compat.py", line 39, in reraise
    raise value
  File "c:\users\manuel.robalinho\appdata\local\programs\python\python37-32\lib\site-packages\flask\app.py", line 1948, in full_dispatch_request
    rv = self.preprocess_request()
  File "c:\users\manuel.robalinho\appdata\local\programs\python\python37-32\lib\site-packages\flask\app.py", line 2242, in preprocess_request
    rv = func()
  File "C:\Users\manuel.robalinho\Google Drive\Trab_Academicos\FLASK\microblog\app\routes.py", line 16, in before_request
    g.locale = str(get_locale())
NameError: name 'g' is not defined
2020-04-12 16:58:30,395 ERROR: Exception on / [GET] [in c:\users\manuel.robalinho\appdata\local\programs\python\python37-32\lib\site-packages\flask\app.py:1892]
Traceback (most recent call last):
  File "c:\users\manuel.robalinho\appdata\local\programs\python\python37-32\lib\site-packages\flask\app.py", line 2447, in wsgi_app
    response = self.full_dispatch_request()
  File "c:\users\manuel.robalinho\appdata\local\programs\python\python37-32\lib\site-packages\flask\app.py", line 1952, in full_dispatch_request
    rv = self.handle_user_exception(e)
  File "c:\users\manuel.robalinho\appdata\local\programs\python\python37-32\lib\site-packages\flask\app.py", line 1821, in handle_user_exception
    reraise(exc_type, exc_value, tb)
  File "c:\users\manuel.robalinho\appdata\local\programs\python\python37-32\lib\site-packages\flask\_compat.py", line 39, in reraise
    raise value
  File "c:\users\manuel.robalinho\appdata\local\programs\python\python37-32\lib\site-packages\flask\app.py", line 1948, in full_dispatch_request
    rv = self.preprocess_request()
  File "c:\users\manuel.robalinho\appdata\local\programs\python\python37-32\lib\site-packages\flask\app.py", line 2242, in preprocess_request
    rv = func()
  File "C:\Users\manuel.robalinho\Google Drive\Trab_Academicos\FLASK\microblog\app\routes.py", line 16, in before_request
    g.locale = str(get_locale())
NameError: name 'g' is not defined
2020-04-12 17:00:47,765 ERROR: Exception on / [GET] [in c:\users\manuel.robalinho\appdata\local\programs\python\python37-32\lib\site-packages\flask\app.py:1892]
Traceback (most recent call last):
  File "c:\users\manuel.robalinho\appdata\local\programs\python\python37-32\lib\site-packages\flask\app.py", line 2447, in wsgi_app
    response = self.full_dispatch_request()
  File "c:\users\manuel.robalinho\appdata\local\programs\python\python37-32\lib\site-packages\flask\app.py", line 1952, in full_dispatch_request
    rv = self.handle_user_exception(e)
  File "c:\users\manuel.robalinho\appdata\local\programs\python\python37-32\lib\site-packages\flask\app.py", line 1821, in handle_user_exception
    reraise(exc_type, exc_value, tb)
  File "c:\users\manuel.robalinho\appdata\local\programs\python\python37-32\lib\site-packages\flask\_compat.py", line 39, in reraise
    raise value
  File "c:\users\manuel.robalinho\appdata\local\programs\python\python37-32\lib\site-packages\flask\app.py", line 1948, in full_dispatch_request
    rv = self.preprocess_request()
  File "c:\users\manuel.robalinho\appdata\local\programs\python\python37-32\lib\site-packages\flask\app.py", line 2242, in preprocess_request
    rv = func()
  File "C:\Users\manuel.robalinho\Google Drive\Trab_Academicos\FLASK\microblog\app\routes.py", line 16, in before_request
    g.locale = str(get_locale())
NameError: name 'g' is not defined
2020-04-12 17:00:57,813 INFO: Microblog startup [in C:\Users\manuel.robalinho\Google Drive\Trab_Academicos\FLASK\microblog\app\__init__.py:53]
2020-04-12 17:03:50,323 INFO: Microblog startup [in C:\Users\manuel.robalinho\Google Drive\Trab_Academicos\FLASK\microblog\app\__init__.py:53]
2020-04-12 17:12:23,690 INFO: Microblog startup [in C:\Users\manuel.robalinho\Google Drive\Trab_Academicos\FLASK\microblog\app\__init__.py:53]
2020-04-12 17:27:36,747 INFO: Microblog startup [in C:\Users\manuel.robalinho\Google Drive\Trab_Academicos\FLASK\microblog\app\__init__.py:53]
